const HttpError = require("../models/http-error");
const { validationResult } = require("express-validator");
const User = require("../models/user");

const getUsers = async (req, res, next) => {
  let users;
  try {
    users = await User.find({}, "-password");
  } catch (err) {
    const error = new HttpError(
      "Fetching users failed, please try again later.",
      500
    );
    return next(error);
  }
  res.json({ users: users.map((user) => user.toObject({ getters: true })) });
};

const signUp = async (req, res, next) => {
  const errors = validationResult(req);
  if (!errors.isEmpty()) {
    return next(new HttpError("Invalid inputs passed", 422));
  }
  const { name, password } = req.body;

  let existingUser;
  try {
    existingUser = await User.findOne({ name: name });
  } catch (err) {
    const error = new HttpError("Sign up failed, try again", 500);
    return next(error);
  }

  if (existingUser) {
    const error = new HttpError("User already exists", 422);
    return next(error);
  }

  const createdUser = new User({ name, password, tasks: [] });
  console.log(name);
  console.log(password);

  try {
    await createdUser.save();
  } catch (err) {
    const error = new HttpError("Signup failed", 500);
    return next(error);
  }

  res.status(201).json({ user: createdUser.toObject({ getters: true }) });
};

const login = async (req, res, next) => {
  const { name, password } = req.body;

  let existingUser;

  try {
    existingUser = await User.findOne({ name: name });
  } catch (err) {
    const error = new HttpError(
      "Logging in failed, please try again later.",
      500
    );
    return next(error);
  }

  if (!existingUser || existingUser.password !== password) {
    const error = new HttpError(
      "Invalid credentials, could not log you in.",
      401
    );
    return next(error);
  }

  res.json({
    message: "Logged in!",
    user: existingUser.toObject({ getters: true }),
  });
};

exports.getUsers = getUsers;
exports.signUp = signUp;
exports.login = login;
